Workbook

Sheet EDT
A2: Matriz Estructura de descomposición de tareas EDT
A4: Etapas | B4: DIAS | C4: HORAS POR ACTIVIDAD O ENTREGABLE | I4: DICCIONARIO EDT
A5: Fase de Planificación | C5: Jefe de Proyecto | D5: Analista Programador | E5: DBA | F5: QA | G5: Diseñador | I5: ROL ACTOR | J5: NOMBRE ACTOR
A6: Acta de Constitución de proyecto | B6: 4 | C6: 20 | D6: 4 | E6: 2 | F6: 2 | G6: 4 | I6: Jefe de Proyecto | J6: Baltazar Roa Soto
A7: Aprobación del Acta | B7: 1 | C7: 6 | D7: 1 | E7: 0 | F7: 1 | G7: 0 | I7: Analista Programador | J7: Joaquin Galarce
A8: Definición de requerimientos Generales | B8: 4 | C8: 12 | D8: 8 | E8: 4 | F8: 4 | G8: 4 | I8: DBA | J8: Angel Pinto
A9: Organización del equipo | B9: 2 | C9: 8 | D9: 2 | E9: 0 | F9: 0 | G9: 0 | I9: QA | J9: Angel Pinto
A10: Fase de Análisis y diseño | C10: Jefe de Proyecto | D10: Analista Programador | E10: DBA | F10: QA | G10: Diseñador | I10: Diseñador | J10: Joaquin Galarce
A11: Captura de requerimientos específicos | B11: 4 | C11: 10 | D11: 10 | E11: 2 | F11: 4 | G11: 4
A12: Documento de casos de uso | B12: 6 | C12: 10 | D12: 20 | E12: 2 | F12: 4 | G12: 2
A13: Documento de avances | B13: 1 | C13: 4 | D13: 2 | E13: 0 | F13: 1 | G13: 1
A14: Prototipos | B14: 7 | C14: 6 | D14: 6 | E14: 0 | F14: 2 | G14: 28
A15: Propuesta ERS | B15: 4 | C15: 10 | D15: 6 | E15: 2 | F15: 2 | G15: 2
A16: Matriz EDT | B16: 1 | C16: 4 | D16: 1 | E16: 1 | F16: 1 | G16: 1
A17: Fase de Desarrollo Inicial | C17: Jefe de Proyecto | D17: Analista Programador | E17: DBA | F17: QA | G17: Diseñador
A18: Implementación ambiente de desarrollo | B18: 4 | C18: 4 | D18: 20 | E18: 6 | F18: 2 | G18: 0
A19: Creacion de los script de tablas base de datos | B19: 5 | C19: 2 | D19: 10 | E19: 20 | F19: 2 | G19: 0
A20: Creacion de los script de consultas PL/SQL | B20: 5 | C20: 2 | D20: 12 | E20: 16 | F20: 2 | G20: 0
A21: Fase de Desarrollo Web | C21: Jefe de Proyecto | D21: Analista Programador | E21: DBA | F21: QA | G21: Diseñador
A22: Módulo de Autenticación y Usuarios
A23: Cuenta administrador (Web) | B23: 2 | C23: 4 | D23: 8 | E23: 0 | F23: 2 | G23: 0
A24: Autentificación de usuario (Web) | B24: 4 | C24: 6 | D24: 18 | E24: 2 | F24: 4 | G24: 0
A25: Inicio de sesión de usuario (Web) | B25: 4 | C25: 6 | D25: 16 | E25: 2 | F25: 4 | G25: 0
A26: Registro de usuario (Web) | B26: 3 | C26: 4 | D26: 12 | E26: 2 | F26: 2 | G26: 0
A27: Perfil de usuario (Web) | B27: 3 | C27: 4 | D27: 10 | E27: 0 | F27: 2 | G27: 4
A28: Administrar usuarios (Web) | B28: 5 | C28: 6 | D28: 20 | E28: 2 | F28: 4 | G28: 0
A29: Administrar credenciales (Web) | B29: 5 | C29: 6 | D29: 18 | E29: 4 | F29: 4 | G29: 0
A30: Módulo Gestión de Productos
A31: Administrar productos | B31: 6 | C31: 6 | D31: 22 | E31: 4 | F31: 4 | G31: 4
A32: Administrar categorías | B32: 5 | C32: 6 | D32: 20 | E32: 2 | F32: 4 | G32: 2
A33: Estados del pedido | B33: 5 | C33: 6 | D33: 20 | E33: 4 | F33: 6 | G33: 0
A34: Carrito de compras | B34: 5 | C34: 6 | D34: 22 | E34: 4 | F34: 4 | G34: 2
A35: Compra de productos | B35: 6 | C35: 6 | D35: 24 | E35: 4 | F35: 6 | G35: 2
A36: Módulo de Reportes y Notificaciones
A37: Notificaciones | B37: 5 | C37: 6 | D37: 18 | E37: 2 | F37: 4 | G37: 0
A38: Reglas y validaciones | B38: 5 | C38: 6 | D38: 18 | E38: 2 | F38: 6 | G38: 0
A39: Reportes básicos | B39: 5 | C39: 6 | D39: 20 | E39: 4 | F39: 6 | G39: 0
A40: UI/UX Web
A41: Diseño responsive | B41: 5 | C41: 4 | D41: 10 | E41: 0 | F41: 2 | G41: 12
A42: Mockups finales | B42: 3 | C42: 2 | D42: 6 | E42: 0 | F42: 2 | G42: 12
...

Sheet Costos Fases
A2: SIGLA | B2: ROL | C2: NOMBRE | D2: VALOR HORA HH | E2: HORAS | F2: FASE PLANIFICACION | H2: COSTO POR HORA
A3: JP | B3: Jefe de Proyecto | C3: =EDT!$J$6 -> Baltazar Roa Soto | D3: 10889 | E3: =SUM(EDT!C6:C9) -> 46 | F3: =D3*E3 -> 500894 | H3: ROL | I3: NOMBRE | J3: COSTO x HORA | K3: Sueldo mes
A4: AP | B4: Analista Programador | C4: =EDT!$J$7 -> Joaquin Galarce | D4: 4307 | E4: =SUM(EDT!D6:D9) -> 15 | F4: =D4*E4 -> 64605 | H4: Jefe de Proyecto | I4: =EDT!$J$6 -> Baltazar Roa Soto | J4: 10889 | K4: 1742314 | L4: Jefe Proyecto: https://cl.computrabajo.com/salarios/project-manager?utm_source=chatgpt.com
A5: DBA | B5: Desarrollador BD | C5: =EDT!$J$8 -> Angel Pinto | D5: 8245 | E5: =SUM(EDT!E6:E9) -> 6 | F5: =D5*E5 -> 49470 | H5: Analista Programador | I5: =EDT!$J$7 -> Joaquin Galarce | J5: 4307 | K5: 689178 | L5: Analista: https://cl.indeed.com/career/analista-programador/salaries
A6: QA | B6: Calidad Y Testing | C6: =EDT!$J$9 -> Angel Pinto | D6: 8786 | E6: =SUM(EDT!F6:F9) -> 7 | F6: =D6*E6 -> 61502 | H6: Administrador BD | I6: =EDT!$J$8 -> Angel Pinto | J6: 8245 | K6: 1319290 | L6: Adminstrador BD: https://cl.indeed.com/career/administrador-de-base-de-datos/salaries?from=top_sb
A7: DI | B7: Diseñador | C7: =EDT!$J$10 -> Joaquin Galarce | D7: 3074 | E7: =SUM(EDT!G6:G9) -> 8 | F7: =D7*E7 -> 24592 | H7: Calidad Y Testing | I7: =EDT!$J$9 -> Angel Pinto | J7: 8786 | K7: 1405766 | L7: Analista QA: https://cl.indeed.com/career/analista-qa/salaries?from=top_sb
B8: TOTAL FASE PLANIFICACION | F8: =SUM(F3:F7) -> 701063 | H8: Diseñador | I8: =EDT!$J$10 -> Joaquin Galarce | J8: 3074 | K8: 491871 | L8: Diseñador Web: https://cl.indeed.com/career/dise%C3%B1ador-web/salaries?from=top_sb
A11: SIGLA | B11: ROL | C11: NOMBRE | D11: VALOR HORA HH | E11: HORAS | F11: FASE ANÁLISIS DISEÑO | H11: COSTO HH POR ROL
A12: JP | B12: Jefe de Proyecto | C12: =EDT!$J$6 -> Baltazar Roa Soto | D12: 10889 | E12: =SUM(EDT!C11:C16) -> 44 | F12: =D12*E12 -> 479116 | H12: Jefe de Proyecto | I12: 10889
A13: AP | B13: Analista Programador | C13: =EDT!$J$7 -> Joaquin Galarce | D13: 4307 | E13: =SUM(EDT!D11:D16) -> 45 | F13: =D13*E13 -> 193815 | H13: Analista Programador | I13: 4307
A14: DBA | B14: Desarrollador BD | C14: =EDT!$J$8 -> Angel Pinto | D14: 8245 | E14: =SUM(EDT!E11:E16) -> 7 | F14: =D14*E14 -> 57715 | H14: Administrador BD | I14: 8245
A15: QA | B15: Calidad Y Testing | C15: =EDT!$J$9 -> Angel Pinto | D15: 8786 | E15: =SUM(EDT!F11:F16) -> 14 | F15: =D15*E15 -> 123004 | H15: Calidad Y Testing | I15: 8786
A16: DI | B16: Diseñador | C16: =EDT!$J$10 -> Joaquin Galarce | D16: 3074 | E16: =SUM(EDT!G11:G16) -> 38 | F16: =D16*E16 -> 116812 | H16: Diseñador | I16: 3074
B17: TOTAL FASE ANÁLISIS DISEÑO | F17: =SUM(F12:F16) -> 970462 | H17: TOTAL HH | I17: =SUM(I12:I16) -> 35301
A20: SIGLA | B20: ROL | C20: NOMBRE | D20: VALOR HORA HH | E20: HORAS | F20: FASE DESARROLLO INICIAL | H20: COSTO POR FASE
A21: JP | B21: Jefe de Proyecto | C21: =EDT!$J$6 -> Baltazar Roa Soto | D21: 10889 | E21: =SUM(EDT!C18:C20) -> 8 | F21: =D21*E21 -> 87112 | H21: Fase de Planificación | I21: =F8 -> 701063
A22: AP | B22: Analista Programador | C22: =EDT!$J$7 -> Joaquin Galarce | D22: 4307 | E22: =SUM(EDT!D18:D20) -> 42 | F22: =D22*E22 -> 180894 | H22: Fase de Análisis y Diseño | I22: =F17 -> 970462
A23: DBA | B23: Desarrollador BD | C23: =EDT!$J$8 -> Angel Pinto | D23: 8245 | E23: =SUM(EDT!E18:E20) -> 42 | F23: =D23*E23 -> 346290 | H23: Fase de Desarrollo | I23: =F26 -> 667012
A24: QA | B24: Calidad Y Testing | C24: =EDT!$J$9 -> Angel Pinto | D24: 8786 | E24: =SUM(EDT!F18:F20) -> 6 | F24: =D24*E24 -> 52716 | H24: Fase Desarrollo Web | I24: =F35 -> 3397512
A25: DI | B25: Diseñador | C25: =EDT!$J$10 -> Joaquin Galarce | D25: 3074 | E25: =SUM(EDT!G18:G20) -> 0 | F25: =D25*E25 -> 0 | H25: Fase Desarrollo App | I25: =F44 -> 2610280
B26: TOTAL FASE DESARROLLO | F26: =SUM(F21:F25) -> 667012 | H26: Fase de Pruebas y QA | I26: =F52 -> 3388264
H27: Fase de Implementación y Cierre | I27: =F60 -> 851872
H28: TOTAL HH FASES | I28: =SUM(I21:I27) -> 12586465
A29: SIGLA | B29: ROL | C29: NOMBRE | D29: VALOR HORA HH | E29: HORAS | F29: FASE DESARROLLO WEB
A30: JP | B30: Jefe de Proyecto | C30: =EDT!$J$6 -> Baltazar Roa Soto | D30: 10889 | E30: =SUM(EDT!C22:C43) -> 94 | F30: =D30*E30 -> 1023566 | H30: Margen | I30: 0.6
A31: AP | B31: Analista Programador | C31: =EDT!$J$7 -> Joaquin Galarce | D31: 4307 | E31: =SUM(EDT!D22:D43) -> 292 | F31: =D31*E31 -> 1257644 | H31: UTILIDAD | I31: =I27*I30 -> 511123.2
A32: DBA | B32: Desarrollador BD | C32: =EDT!$J$8 -> Angel Pinto | D32: 8245 | E32: =SUM(EDT!E22:E43) -> 38 | F32: =D32*E32 -> 313310 | H32: PRECIO FINAL | I32: =I27+I31 -> 1362995.2
A33: QA | B33: Calidad Y Testing | C33: =EDT!$J$9 -> Angel Pinto | D33: 8786 | E33: =SUM(EDT!F22:F43) -> 76 | F33: =D33*E33 -> 667736
A34: DI | B34: Diseñador | C34: =EDT!$J$10 -> Joaquin Galarce | D34: 3074 | E34: =SUM(EDT!G22:G43) -> 44 | F34: =D34*E34 -> 135256
B35: TOTAL FASE DESARROLLO WEB | F35: =SUM(F30:F34) -> 3397512
A38: SIGLA | B38: ROL | C38: NOMBRE | D38: VALOR HORA HH | E38: HORAS | F38: FASE DESARROLLO APP
A39: JP | B39: Jefe de Proyecto | C39: =EDT!$J$6 -> Baltazar Roa Soto | D39: 10889 | E39: =SUM(EDT!C45:C62) -> 68 | F39: =D39*E39 -> 740452
A40: AP | B40: Analista Programador | C40: =EDT!$J$7 -> Joaquin Galarce | D40: 4307 | E40: =SUM(EDT!D45:D62) -> 222 | F40: =D40*E40 -> 956154
A41: DBA | B41: Desarrollador BD | C41: =EDT!$J$8 -> Angel Pinto | D41: 8245 | E41: =SUM(EDT!E45:E62) -> 26 | F41: =D41*E41 -> 214370
A42: QA | B42: Calidad Y Testing | C42: =EDT!$J$9 -> Angel Pinto | D42: 8786 | E42: =SUM(EDT!F45:F62) -> 60 | F42: =D42*E42 -> 527160
A43: DI | B43: Diseñador | C43: =EDT!$J$10 -> Joaquin Galarce | D43: 3074 | E43: =SUM(EDT!G45:G62) -> 56 | F43: =D43*E43 -> 172144
B44: TOTAL FASE DESARROLLO APP | F44: =SUM(F39:F43) -> 2610280
A46: SIGLA | B46: ROL | C46: NOMBRE | D46: VALOR HORA HH | E46: HORAS | F46: FASE PRUEBAS Y QA
A47: JP | B47: Jefe de Proyecto | C47: =EDT!$J$6 -> Baltazar Roa Soto | D47: 10889 | E47: =SUM(EDT!C64:C85) -> 54 | F47: =D47*E47 -> 588006
A48: AP | B48: Analista Programador | C48: =EDT!$J$7 -> Joaquin Galarce | D48: 4307 | E48: =SUM(EDT!D64:D85) -> 116 | F48: =D48*E48 -> 499612
...

Sheet Detalle Valores
B3: Rol | C3: Jefe de Proyecto | D3: Analista Programador | E3: DBA | F3: QA | G3: Diseñador
B4: Nombre | C4: Baltazar Roa | D4: Joaquín Galarce | E4: Ángel Pinto | F4: (por definir) | G4: Joaquín Galarce
B5: Horas Por Día | C5: 6 h/día | D5: 8 h/día | E5: 4 h/día | F5: 6 h/día en semanas de pruebas / 2 h/día el resto | G5: 5 h/día cuando esté dedicado a diseño
B6: Notas De Uso / Justificación | C6: Coordinación, seguimiento, reuniones, revisión de entregables (≈75% de una jornada estándar). | D6: Desarrollo, análisis técnico. | E6: Diseño/ajustes de BD, migraciones, respaldos (picos a 6 h/día en semanas críticas). | F6: Preparación de casos, pruebas, reportes de defectos. | G6: Si Joaquín combina dev + diseño en la misma semana, no exceder 8 h/día totales (p.ej., 6h dev + 2h diseño).
